Workbook

Sheet 조편성
A1: 조 | B1: 순번 | C1: 성명 | D1: 학과 | E1: 학년 | F1: 학번 | G1: 국적 | H1: 성별(이름 기준 추정) | I1: 비고
A2: 1조 | B2: 1 | C2: ZUO HUIJIE | D2: 미디어학과 | E2: 1 | F2: 2026106288 | G2: 중국 | H2: 여 | I2: 유학생 1학년 / 성별 불확실(확인 필요)
A3: 1조 | B3: 2 | C3: 장재원 | D3: 미디어학과 | E3: 1 | F3: 2026105502 | G3: 한국 | H3: 남
A4: 1조 | B4: 3 | C4: SU YADANAR HTUT | D4: 미디어학과 | E4: 2 | F4: 2025106109 | G4: 미얀마 | H4: 여
A5: 1조 | B5: 4 | C5: 조수현 | D5: 미디어학과 | E5: 2 | F5: 2025102847 | G5: 한국 | H5: 여 | I5: 성별 불확실(확인 필요)
A6: 1조 | B6: 5 | C6: 최경아 | D6: 미디어학과 | E6: 2 | F6: 2025102853 | G6: 한국 | H6: 여
A7: 1조 | B7: 6 | C7: 추윤서 | D7: 미디어학과 | E7: 3 | F7: 2024102700 | G7: 한국 | H7: 여
A8: 2조 | B8: 1 | C8: LIANG YINGYING | D8: 미디어학과 | E8: 1 | F8: 2026105931 | G8: 중국 | H8: 여 | I8: 유학생 1학년
A9: 2조 | B9: 2 | C9: 장예원 | D9: 자율전공학부 | E9: 1 | F9: 2026104618 | G9: 한국 | H9: 여
A10: 2조 | B10: 3 | C10: 강아람 | D10: 미디어학과 | E10: 2 | F10: 2025102767 | G10: 한국 | H10: 여
A11: 2조 | B11: 4 | C11: 배지민 | D11: 미디어학과 | E11: 2 | F11: 2025105321 | G11: 한국 | H11: 여 | I11: 성별 불확실(확인 필요)
A12: 2조 | B12: 5 | C12: 이정빈 | D12: 미디어학과 | E12: 2 | F12: 2025102833 | G12: 한국 | H12: 남 | I12: 성별 불확실(확인 필요)
A13: 2조 | B13: 6 | C13: 정병훈 | D13: 미디어학과 | E13: 3 | F13: 2022103088 | G13: 한국 | H13: 남
A14: 3조 | B14: 1 | C14: JIN HUIJING | D14: 미디어학과 | E14: 1 | F14: 2026106258 | G14: 중국 | H14: 여 | I14: 유학생 1학년 / 성별 불확실(확인 필요)
A15: 3조 | B15: 2 | C15: 양창훈 | D15: Hospitality경영학과 | E15: 1 | F15: 2026104842 | G15: 한국 | H15: 남
A16: 3조 | B16: 3 | C16: 김단아 | D16: 미디어학과 | E16: 2 | F16: 2025102773 | G16: 한국 | H16: 여
A17: 3조 | B17: 4 | C17: 김민서 | D17: 미디어학과 | E17: 2 | F17: 2025102774 | G17: 한국 | H17: 여 | I17: 성별 불확실(확인 필요)
A18: 3조 | B18: 5 | C18: 황준선 | D18: 미디어학과 | E18: 2 | F18: 2023102757 | G18: 한국 | H18: 남
A19: 3조 | B19: 6 | C19: ZANGENEH ROUMINA | D19: 미디어학과 | E19: 3 | F19: 2024100113 | G19: 이란 | H19: 여
A20: 4조 | B20: 1 | C20: WU YUDUO | D20: 미디어학과 | E20: 1 | F20: 2026105942 | G20: 중국 | H20: 여 | I20: 유학생 1학년 / 성별 불확실(확인 필요)
A21: 4조 | B21: 2 | C21: 최윤서 | D21: 미디어학과 | E21: 1 | F21: 2026104713 | G21: 한국 | H21: 여
A22: 4조 | B22: 3 | C22: 김진서 | D22: 미디어학과 | E22: 2 | F22: 2025102790 | G22: 한국 | H22: 남 | I22: 성별 불확실(확인 필요)
A23: 4조 | B23: 4 | C23: 신승현 | D23: 미디어학과 | E23: 2 | F23: 2025102814 | G23: 한국 | H23: 남
A24: 4조 | B24: 5 | C24: 이다윤 | D24: 미디어학과 | E24: 2 | F24: 2025103573 | G24: 한국 | H24: 여
A25: 4조 | B25: 6 | C25: 이주은 | D25: 미디어학과 | E25: 3 | F25: 2024102675 | G25: 한국 | H25: 여
A26: 5조 | B26: 1 | C26: 이하진 | D26: 미디어학과 | E26: 1 | F26: 2026104700 | G26: 한국 | H26: 여 | I26: 성별 불확실(확인 필요)
A27: 5조 | B27: 2 | C27: 도정서 | D27: 미디어학과 | E27: 2 | F27: 2025100765 | G27: 한국 | H27: 남 | I27: 성별 불확실(확인 필요)
A28: 5조 | B28: 3 | C28: 신은채 | D28: 미디어학과 | E28: 2 | F28: 2025102815 | G28: 한국 | H28: 여
A29: 5조 | B29: 4 | C29: 이유진 | D29: 미디어학과 | E29: 2 | F29: 2025102831 | G29: 한국 | H29: 여
A30: 5조 | B30: 5 | C30: 윤서은 | D30: 국어국문학과 | E30: 3 | F30: 2024101369 | G30: 한국 | H30: 여
A31: 5조 | B31: 6 | C31: HE XINYUE | D31: 미디어학과 | E31: 4 | F31: 2021106058 | G31: 중국 | H31: 여 | I31: 성별 불확실(확인 필요)
A32: 6조 | B32: 1 | C32: LI YUNTING | D32: 미디어학과 | E32: 1 | F32: 2026105928 | G32: 중국 | H32: 여 | I32: 유학생 1학년 / 성별 불확실(확인 필요)
A33: 6조 | B33: 2 | C33: 김가람 | D33: 미디어학과 | E33: 2 | F33: 2024102616 | G33: 한국 | H33: 여 | I33: 성별 불확실(확인 필요)
A34: 6조 | B34: 3 | C34: 김준영 | D34: 미디어학과 | E34: 2 | F34: 2025102785 | G34: 한국 | H34: 남
A35: 6조 | B35: 4 | C35: 김지안 | D35: 미디어학과 | E35: 2 | F35: 2025102787 | G35: 한국 | H35: 여 | I35: 성별 불확실(확인 필요)
A36: 6조 | B36: 5 | C36: 신채이 | D36: 철학과 | E36: 3 | F36: 2024101458 | G36: 한국 | H36: 여
A37: 6조 | B37: 6 | C37: Emily Chong Jun Yee | D37: 미디어학과 | E37: 4 | F37: 2023100106 | G37: 말레이시아 | H37: 여
A38: 7조 | B38: 1 | C38: XU ZIYU | D38: 미디어학과 | E38: 1 | F38: 2026105944 | G38: 중국 | H38: 남 | I38: 유학생 1학년 / 성별 불확실(확인 필요)
A39: 7조 | B39: 2 | C39: 김지원 | D39: 미디어학과 | E39: 1 | F39: 2026104660 | G39: 한국 | H39: 여 | I39: 성별 불확실(확인 필요)
A40: 7조 | B40: 3 | C40: 김규린 | D40: 영어영문학과 | E40: 2 | F40: 2025102426 | G40: 한국 | H40: 여
...

Sheet 조별 요약
A1: 조 | B1: 인원 | C1: 1학년 | D1: 2학년 | E1: 3학년 | F1: 4학년 | G1: 유학생(전체) | H1: 유학생 1학년 | I1: 한국 | J1: 중국 | K1: 기타 국적 | L1: 남(추정) | M1: 여(추정) | N1: 미디어학과 | O1: 타 학과
A2: 1조 | B2: =COUNTIF('조편성'!$A$2:$A$61,A2) | C2: =COUNTIFS('조편성'!$A$2:$A$61,$A2,'조편성'!$E$2:$E$61,1) | D2: =COUNTIFS('조편성'!$A$2:$A$61,$A2,'조편성'!$E$2:$E$61,2) | E2: =COUNTIFS('조편성'!$A$2:$A$61,$A2,'조편성'!$E$2:$E$61,3) | F2: =COUNTIFS('조편성'!$A$2:$A$61,$A2,'조편성'!$E$2:$E$61,4) | G2: =B2-COUNTIFS('조편성'!$A$2:$A$61,$A2,'조편성'!$G$2:$G$61,"한국") | H2: =COUNTIFS('조편성'!$A$2:$A$61,$A2,'조편성'!$I$2:$I$61,"*유학생 1학년*") | I2: =COUNTIFS('조편성'!$A$2:$A$61,$A2,'조편성'!$G$2:$G$61,"한국") | J2: =COUNTIFS('조편성'!$A$2:$A$61,$A2,'조편성'!$G$2:$G$61,"중국") | K2: =G2-J2 | L2: =COUNTIFS('조편성'!$A$2:$A$61,$A2,'조편성'!$H$2:$H$61,"남") | M2: =COUNTIFS('조편성'!$A$2:$A$61,$A2,'조편성'!$H$2:$H$61,"여") | N2: =COUNTIFS('조편성'!$A$2:$A$61,$A2,'조편성'!$D$2:$D$61,"미디어학과") | O2: =B2-N2
A3: 2조 | B3: =COUNTIF('조편성'!$A$2:$A$61,A3) | C3: =COUNTIFS('조편성'!$A$2:$A$61,$A3,'조편성'!$E$2:$E$61,1) | D3: =COUNTIFS('조편성'!$A$2:$A$61,$A3,'조편성'!$E$2:$E$61,2) | E3: =COUNTIFS('조편성'!$A$2:$A$61,$A3,'조편성'!$E$2:$E$61,3) | F3: =COUNTIFS('조편성'!$A$2:$A$61,$A3,'조편성'!$E$2:$E$61,4) | G3: =B3-COUNTIFS('조편성'!$A$2:$A$61,$A3,'조편성'!$G$2:$G$61,"한국") | H3: =COUNTIFS('조편성'!$A$2:$A$61,$A3,'조편성'!$I$2:$I$61,"*유학생 1학년*") | I3: =COUNTIFS('조편성'!$A$2:$A$61,$A3,'조편성'!$G$2:$G$61,"한국") | J3: =COUNTIFS('조편성'!$A$2:$A$61,$A3,'조편성'!$G$2:$G$61,"중국") | K3: =G3-J3 | L3: =COUNTIFS('조편성'!$A$2:$A$61,$A3,'조편성'!$H$2:$H$61,"남") | M3: =COUNTIFS('조편성'!$A$2:$A$61,$A3,'조편성'!$H$2:$H$61,"여") | N3: =COUNTIFS('조편성'!$A$2:$A$61,$A3,'조편성'!$D$2:$D$61,"미디어학과") | O3: =B3-N3
A4: 3조 | B4: =COUNTIF('조편성'!$A$2:$A$61,A4) | C4: =COUNTIFS('조편성'!$A$2:$A$61,$A4,'조편성'!$E$2:$E$61,1) | D4: =COUNTIFS('조편성'!$A$2:$A$61,$A4,'조편성'!$E$2:$E$61,2) | E4: =COUNTIFS('조편성'!$A$2:$A$61,$A4,'조편성'!$E$2:$E$61,3) | F4: =COUNTIFS('조편성'!$A$2:$A$61,$A4,'조편성'!$E$2:$E$61,4) | G4: =B4-COUNTIFS('조편성'!$A$2:$A$61,$A4,'조편성'!$G$2:$G$61,"한국") | H4: =COUNTIFS('조편성'!$A$2:$A$61,$A4,'조편성'!$I$2:$I$61,"*유학생 1학년*") | I4: =COUNTIFS('조편성'!$A$2:$A$61,$A4,'조편성'!$G$2:$G$61,"한국") | J4: =COUNTIFS('조편성'!$A$2:$A$61,$A4,'조편성'!$G$2:$G$61,"중국") | K4: =G4-J4 | L4: =COUNTIFS('조편성'!$A$2:$A$61,$A4,'조편성'!$H$2:$H$61,"남") | M4: =COUNTIFS('조편성'!$A$2:$A$61,$A4,'조편성'!$H$2:$H$61,"여") | N4: =COUNTIFS('조편성'!$A$2:$A$61,$A4,'조편성'!$D$2:$D$61,"미디어학과") | O4: =B4-N4
A5: 4조 | B5: =COUNTIF('조편성'!$A$2:$A$61,A5) | C5: =COUNTIFS('조편성'!$A$2:$A$61,$A5,'조편성'!$E$2:$E$61,1) | D5: =COUNTIFS('조편성'!$A$2:$A$61,$A5,'조편성'!$E$2:$E$61,2) | E5: =COUNTIFS('조편성'!$A$2:$A$61,$A5,'조편성'!$E$2:$E$61,3) | F5: =COUNTIFS('조편성'!$A$2:$A$61,$A5,'조편성'!$E$2:$E$61,4) | G5: =B5-COUNTIFS('조편성'!$A$2:$A$61,$A5,'조편성'!$G$2:$G$61,"한국") | H5: =COUNTIFS('조편성'!$A$2:$A$61,$A5,'조편성'!$I$2:$I$61,"*유학생 1학년*") | I5: =COUNTIFS('조편성'!$A$2:$A$61,$A5,'조편성'!$G$2:$G$61,"한국") | J5: =COUNTIFS('조편성'!$A$2:$A$61,$A5,'조편성'!$G$2:$G$61,"중국") | K5: =G5-J5 | L5: =COUNTIFS('조편성'!$A$2:$A$61,$A5,'조편성'!$H$2:$H$61,"남") | M5: =COUNTIFS('조편성'!$A$2:$A$61,$A5,'조편성'!$H$2:$H$61,"여") | N5: =COUNTIFS('조편성'!$A$2:$A$61,$A5,'조편성'!$D$2:$D$61,"미디어학과") | O5: =B5-N5
A6: 5조 | B6: =COUNTIF('조편성'!$A$2:$A$61,A6) | C6: =COUNTIFS('조편성'!$A$2:$A$61,$A6,'조편성'!$E$2:$E$61,1) | D6: =COUNTIFS('조편성'!$A$2:$A$61,$A6,'조편성'!$E$2:$E$61,2) | E6: =COUNTIFS('조편성'!$A$2:$A$61,$A6,'조편성'!$E$2:$E$61,3) | F6: =COUNTIFS('조편성'!$A$2:$A$61,$A6,'조편성'!$E$2:$E$61,4) | G6: =B6-COUNTIFS('조편성'!$A$2:$A$61,$A6,'조편성'!$G$2:$G$61,"한국") | H6: =COUNTIFS('조편성'!$A$2:$A$61,$A6,'조편성'!$I$2:$I$61,"*유학생 1학년*") | I6: =COUNTIFS('조편성'!$A$2:$A$61,$A6,'조편성'!$G$2:$G$61,"한국") | J6: =COUNTIFS('조편성'!$A$2:$A$61,$A6,'조편성'!$G$2:$G$61,"중국") | K6: =G6-J6 | L6: =COUNTIFS('조편성'!$A$2:$A$61,$A6,'조편성'!$H$2:$H$61,"남") | M6: =COUNTIFS('조편성'!$A$2:$A$61,$A6,'조편성'!$H$2:$H$61,"여") | N6: =COUNTIFS('조편성'!$A$2:$A$61,$A6,'조편성'!$D$2:$D$61,"미디어학과") | O6: =B6-N6
A7: 6조 | B7: =COUNTIF('조편성'!$A$2:$A$61,A7) | C7: =COUNTIFS('조편성'!$A$2:$A$61,$A7,'조편성'!$E$2:$E$61,1) | D7: =COUNTIFS('조편성'!$A$2:$A$61,$A7,'조편성'!$E$2:$E$61,2) | E7: =COUNTIFS('조편성'!$A$2:$A$61,$A7,'조편성'!$E$2:$E$61,3) | F7: =COUNTIFS('조편성'!$A$2:$A$61,$A7,'조편성'!$E$2:$E$61,4) | G7: =B7-COUNTIFS('조편성'!$A$2:$A$61,$A7,'조편성'!$G$2:$G$61,"한국") | H7: =COUNTIFS('조편성'!$A$2:$A$61,$A7,'조편성'!$I$2:$I$61,"*유학생 1학년*") | I7: =COUNTIFS('조편성'!$A$2:$A$61,$A7,'조편성'!$G$2:$G$61,"한국") | J7: =COUNTIFS('조편성'!$A$2:$A$61,$A7,'조편성'!$G$2:$G$61,"중국") | K7: =G7-J7 | L7: =COUNTIFS('조편성'!$A$2:$A$61,$A7,'조편성'!$H$2:$H$61,"남") | M7: =COUNTIFS('조편성'!$A$2:$A$61,$A7,'조편성'!$H$2:$H$61,"여") | N7: =COUNTIFS('조편성'!$A$2:$A$61,$A7,'조편성'!$D$2:$D$61,"미디어학과") | O7: =B7-N7
A8: 7조 | B8: =COUNTIF('조편성'!$A$2:$A$61,A8) | C8: =COUNTIFS('조편성'!$A$2:$A$61,$A8,'조편성'!$E$2:$E$61,1) | D8: =COUNTIFS('조편성'!$A$2:$A$61,$A8,'조편성'!$E$2:$E$61,2) | E8: =COUNTIFS('조편성'!$A$2:$A$61,$A8,'조편성'!$E$2:$E$61,3) | F8: =COUNTIFS('조편성'!$A$2:$A$61,$A8,'조편성'!$E$2:$E$61,4) | G8: =B8-COUNTIFS('조편성'!$A$2:$A$61,$A8,'조편성'!$G$2:$G$61,"한국") | H8: =COUNTIFS('조편성'!$A$2:$A$61,$A8,'조편성'!$I$2:$I$61,"*유학생 1학년*") | I8: =COUNTIFS('조편성'!$A$2:$A$61,$A8,'조편성'!$G$2:$G$61,"한국") | J8: =COUNTIFS('조편성'!$A$2:$A$61,$A8,'조편성'!$G$2:$G$61,"중국") | K8: =G8-J8 | L8: =COUNTIFS('조편성'!$A$2:$A$61,$A8,'조편성'!$H$2:$H$61,"남") | M8: =COUNTIFS('조편성'!$A$2:$A$61,$A8,'조편성'!$H$2:$H$61,"여") | N8: =COUNTIFS('조편성'!$A$2:$A$61,$A8,'조편성'!$D$2:$D$61,"미디어학과") | O8: =B8-N8
A9: 8조 | B9: =COUNTIF('조편성'!$A$2:$A$61,A9) | C9: =COUNTIFS('조편성'!$A$2:$A$61,$A9,'조편성'!$E$2:$E$61,1) | D9: =COUNTIFS('조편성'!$A$2:$A$61,$A9,'조편성'!$E$2:$E$61,2) | E9: =COUNTIFS('조편성'!$A$2:$A$61,$A9,'조편성'!$E$2:$E$61,3) | F9: =COUNTIFS('조편성'!$A$2:$A$61,$A9,'조편성'!$E$2:$E$61,4) | G9: =B9-COUNTIFS('조편성'!$A$2:$A$61,$A9,'조편성'!$G$2:$G$61,"한국") | H9: =COUNTIFS('조편성'!$A$2:$A$61,$A9,'조편성'!$I$2:$I$61,"*유학생 1학년*") | I9: =COUNTIFS('조편성'!$A$2:$A$61,$A9,'조편성'!$G$2:$G$61,"한국") | J9: =COUNTIFS('조편성'!$A$2:$A$61,$A9,'조편성'!$G$2:$G$61,"중국") | K9: =G9-J9 | L9: =COUNTIFS('조편성'!$A$2:$A$61,$A9,'조편성'!$H$2:$H$61,"남") | M9: =COUNTIFS('조편성'!$A$2:$A$61,$A9,'조편성'!$H$2:$H$61,"여") | N9: =COUNTIFS('조편성'!$A$2:$A$61,$A9,'조편성'!$D$2:$D$61,"미디어학과") | O9: =B9-N9
A10: 9조 | B10: =COUNTIF('조편성'!$A$2:$A$61,A10) | C10: =COUNTIFS('조편성'!$A$2:$A$61,$A10,'조편성'!$E$2:$E$61,1) | D10: =COUNTIFS('조편성'!$A$2:$A$61,$A10,'조편성'!$E$2:$E$61,2) | E10: =COUNTIFS('조편성'!$A$2:$A$61,$A10,'조편성'!$E$2:$E$61,3) | F10: =COUNTIFS('조편성'!$A$2:$A$61,$A10,'조편성'!$E$2:$E$61,4) | G10: =B10-COUNTIFS('조편성'!$A$2:$A$61,$A10,'조편성'!$G$2:$G$61,"한국") | H10: =COUNTIFS('조편성'!$A$2:$A$61,$A10,'조편성'!$I$2:$I$61,"*유학생 1학년*") | I10: =COUNTIFS('조편성'!$A$2:$A$61,$A10,'조편성'!$G$2:$G$61,"한국") | J10: =COUNTIFS('조편성'!$A$2:$A$61,$A10,'조편성'!$G$2:$G$61,"중국") | K10: =G10-J10 | L10: =COUNTIFS('조편성'!$A$2:$A$61,$A10,'조편성'!$H$2:$H$61,"남") | M10: =COUNTIFS('조편성'!$A$2:$A$61,$A10,'조편성'!$H$2:$H$61,"여") | N10: =COUNTIFS('조편성'!$A$2:$A$61,$A10,'조편성'!$D$2:$D$61,"미디어학과") | O10: =B10-N10
A11: 10조 | B11: =COUNTIF('조편성'!$A$2:$A$61,A11) | C11: =COUNTIFS('조편성'!$A$2:$A$61,$A11,'조편성'!$E$2:$E$61,1) | D11: =COUNTIFS('조편성'!$A$2:$A$61,$A11,'조편성'!$E$2:$E$61,2) | E11: =COUNTIFS('조편성'!$A$2:$A$61,$A11,'조편성'!$E$2:$E$61,3) | F11: =COUNTIFS('조편성'!$A$2:$A$61,$A11,'조편성'!$E$2:$E$61,4) | G11: =B11-COUNTIFS('조편성'!$A$2:$A$61,$A11,'조편성'!$G$2:$G$61,"한국") | H11: =COUNTIFS('조편성'!$A$2:$A$61,$A11,'조편성'!$I$2:$I$61,"*유학생 1학년*") | I11: =COUNTIFS('조편성'!$A$2:$A$61,$A11,'조편성'!$G$2:$G$61,"한국") | J11: =COUNTIFS('조편성'!$A$2:$A$61,$A11,'조편성'!$G$2:$G$61,"중국") | K11: =G11-J11 | L11: =COUNTIFS('조편성'!$A$2:$A$61,$A11,'조편성'!$H$2:$H$61,"남") | M11: =COUNTIFS('조편성'!$A$2:$A$61,$A11,'조편성'!$H$2:$H$61,"여") | N11: =COUNTIFS('조편성'!$A$2:$A$61,$A11,'조편성'!$D$2:$D$61,"미디어학과") | O11: =B11-N11
A12: 합계 | B12: =SUM(B2:B11) | C12: =SUM(C2:C11) | D12: =SUM(D2:D11) | E12: =SUM(E2:E11) | F12: =SUM(F2:F11) | G12: =SUM(G2:G11) | H12: =SUM(H2:H11) | I12: =SUM(I2:I11) | ... O12: =SUM(O2:O11)

Sheet 검토·유의사항
A1: [편성 기준(교수님 요청)]
A2: - 총 60명을 6명씩 10개 조로 편성
A3: - 학년·국적·성별·전공을 고르게 분산
A4: - 유학생 1학년(8명, 전원 중국 국적)은 서로 다른 조에 1명씩 배치
A6: [유의사항]
A7: - 출석부(원본)에는 성별 정보가 없어 성별은 이름만으로 추정했습니다. 노란색 칸은 불확실하므로 실제와 다르면 알려주세요(수정 시 조 재조정 필요할 수 있음).
A8: - 유학생 1학년이 8명이라 10개 조 전부에 1명씩 배치하는 것은 불가능합니다. 대신 유학생 1학년이 없는 2개 조에도 유학생(상급학년)을 1명 이상 배치해 모든 조에 유학생이 최소 1명 있도록 했습니다.
A9: - 국적란이 비어 있는 학생은 한국 국적으로 처리했습니다(원본 기준).
A10: - 원본의 날짜(09/01 등)는 수강정정일이므로 편성에 사용하지 않았습니다.
A11: - 학과: 미디어학과 54명, 철학 2, 영문 1, 국문 1, Hospitality경영 1, 자율전공 1 → 타 학과 6명을 서로 다른 조에 분산(철학 2명도 다른 조)
